<?xml version="1.0" ?>
<!-- =================================================================================== -->
<!-- |    This document was autogenerated by xacro from my_vehicle.xacro               | -->
<!-- |    EDITING THIS FILE BY HAND IS NOT RECOMMENDED                                 | -->
<!-- =================================================================================== -->
<!--
  vehicle.xacro
  A simple example of using Xacro to create a vehicle-like robot
  with a chassis and four wheels.
-->
<robot name="xacro_vehicle">
  <link name="base_link">
    <visual>
      <geometry>
        <box size="1.0 0.6 0.2"/>
      </geometry>
      <material name="blue">
        <color rgba="0.2 0.2 0.8 1"/>
      </material>
    </visual>
  </link>
  <link name="front_left_wheel">
    <visual>
      <geometry>
        <cylinder length="0.05" radius="0.15"/>
      </geometry>
      <material name="black">
        <color rgba="0.1 0.1 0.1 1"/>
      </material>
      <origin rpy="1.5708 0 0"/>
      <!-- rotate to lay flat -->
    </visual>
    <inertial>
      <mass value="1.0"/>
      <origin rpy="0 0 0" xyz="0 0 0"/>
      <inertia ixx="0.1" ixy="0.0" ixz="0.0" iyy="0.1" iyz="0.0" izz="0.1"/>
    </inertial>
  </link>
  <joint name="joint_front_left_wheel" type="continuous">
    <parent link="base_link"/>
    <child link="front_left_wheel"/>
    <origin rpy="0 0 0" xyz="0.35  0.25 -0.15"/>
    <axis xyz="0 1 0"/>
    <!-- wheel spins around the y-axis -->
  </joint>
  <link name="front_right_wheel">
    <visual>
      <geometry>
        <cylinder length="0.05" radius="0.15"/>
      </geometry>
      <material name="black">
        <color rgba="0.1 0.1 0.1 1"/>
      </material>
      <origin rpy="1.5708 0 0"/>
      <!-- rotate to lay flat -->
    </visual>
    <inertial>
      <mass value="1.0"/>
      <origin rpy="0 0 0" xyz="0 0 0"/>
      <inertia ixx="0.1" ixy="0.0" ixz="0.0" iyy="0.1" iyz="0.0" izz="0.1"/>
    </inertial>
  </link>
  <joint name="joint_front_right_wheel" type="continuous">
    <parent link="base_link"/>
    <child link="front_right_wheel"/>
    <origin rpy="0 0 0" xyz="0.35 -0.25 -0.15"/>
    <axis xyz="0 1 0"/>
    <!-- wheel spins around the y-axis -->
  </joint>
  <link name="rear_left_wheel">
    <visual>
      <geometry>
        <cylinder length="0.05" radius="0.15"/>
      </geometry>
      <material name="black">
        <color rgba="0.1 0.1 0.1 1"/>
      </material>
      <origin rpy="1.5708 0 0"/>
      <!-- rotate to lay flat -->
    </visual>
    <inertial>
      <mass value="1.0"/>
      <origin rpy="0 0 0" xyz="0 0 0"/>
      <inertia ixx="0.1" ixy="0.0" ixz="0.0" iyy="0.1" iyz="0.0" izz="0.1"/>
    </inertial>
  </link>
  <joint name="joint_rear_left_wheel" type="continuous">
    <parent link="base_link"/>
    <child link="rear_left_wheel"/>
    <origin rpy="0 0 0" xyz="-0.35  0.25 -0.15"/>
    <axis xyz="0 1 0"/>
    <!-- wheel spins around the y-axis -->
  </joint>
  <link name="rear_right_wheel">
    <visual>
      <geometry>
        <cylinder length="0.05" radius="0.15"/>
      </geometry>
      <material name="black">
        <color rgba="0.1 0.1 0.1 1"/>
      </material>
      <origin rpy="1.5708 0 0"/>
      <!-- rotate to lay flat -->
    </visual>
    <inertial>
      <mass value="1.0"/>
      <origin rpy="0 0 0" xyz="0 0 0"/>
      <inertia ixx="0.1" ixy="0.0" ixz="0.0" iyy="0.1" iyz="0.0" izz="0.1"/>
    </inertial>
  </link>
  <joint name="joint_rear_right_wheel" type="continuous">
    <parent link="base_link"/>
    <child link="rear_right_wheel"/>
    <origin rpy="0 0 0" xyz="-0.35 -0.25 -0.15"/>
    <axis xyz="0 1 0"/>
    <!-- wheel spins around the y-axis -->
  </joint>
  <!-- ========== ROS 2 Control Setup ========== -->
  <ros2_control name="VehicleSystem" type="system">
    <hardware>
      <plugin>ros2_control_demo_hardware/DiffBotSystemHardware</plugin>
    </hardware>
    <joint name="joint_rear_left_wheel">
      <command_interface name="velocity"/>
      <state_interface name="velocity"/>
      <state_interface name="position"/>
    </joint>
    <joint name="joint_rear_right_wheel">
      <command_interface name="velocity"/>
      <state_interface name="velocity"/>
      <state_interface name="position"/>
    </joint>
  </ros2_control>
  <!-- Transmission interfaces -->
  <transmission name="rear_left_wheel_trans">
    <type>transmission_interface/SimpleTransmission</type>
    <joint name="joint_rear_left_wheel">
      <hardware_interface>hardware_interface/VelocityJointInterface</hardware_interface>
    </joint>
    <actuator name="rear_left_motor">
      <hardware_interface>hardware_interface/VelocityJointInterface</hardware_interface>
      <mechanical_reduction>1</mechanical_reduction>
    </actuator>
  </transmission>
  <transmission name="rear_right_wheel_trans">
    <type>transmission_interface/SimpleTransmission</type>
    <joint name="joint_rear_right_wheel">
      <hardware_interface>hardware_interface/VelocityJointInterface</hardware_interface>
    </joint>
    <actuator name="rear_right_motor">
      <hardware_interface>hardware_interface/VelocityJointInterface</hardware_interface>
      <mechanical_reduction>1</mechanical_reduction>
    </actuator>
  </transmission>
</robot>
